INFO : 2018-10-14 19:31:56,121 : Running with settings
NFS_PATH:/home/nfs
HOST_NAME:localhost
PORT:8000
CLIENT_VIDEO_STATUS_URL:http://${WEB_IP}:${WEB_PORT}/api/contest/videos/status/
Running with settings
NFS_PATH:/home/nfs
HOST_NAME:localhost
PORT:8000
CLIENT_VIDEO_STATUS_URL:http://${WEB_IP}:${WEB_PORT}/api/contest/videos/status/
/usr/local/lib/python3.6/site-packages/celery/platforms.py:796: RuntimeWarning: You're running the worker with superuser privileges: this is
absolutely not recommended!

Please specify a different user using the --uid option.

User information: uid=0 euid=0 gid=0 egid=0

  uid=uid, euid=euid, gid=gid, egid=egid,
[2018-10-14 19:31:56,235: ERROR/MainProcess] consumer: Cannot connect to amqp://aucar:**@127.0.0.1:5672/aucar: [Errno 111] Connection refused.
Trying again in 2.00 seconds...

[2018-10-14 19:31:58,248: ERROR/MainProcess] consumer: Cannot connect to amqp://aucar:**@127.0.0.1:5672/aucar: [Errno 111] Connection refused.
Trying again in 4.00 seconds...

[2018-10-14 19:32:02,267: ERROR/MainProcess] consumer: Cannot connect to amqp://aucar:**@127.0.0.1:5672/aucar: [Errno 111] Connection refused.
Trying again in 6.00 seconds...

[2018-10-14 19:32:08,284: ERROR/MainProcess] consumer: Cannot connect to amqp://aucar:**@127.0.0.1:5672/aucar: [Errno 111] Connection refused.
Trying again in 8.00 seconds...

[2018-10-14 19:32:16,304: ERROR/MainProcess] consumer: Cannot connect to amqp://aucar:**@127.0.0.1:5672/aucar: [Errno 111] Connection refused.
Trying again in 10.00 seconds...

[2018-10-14 19:32:26,326: ERROR/MainProcess] consumer: Cannot connect to amqp://aucar:**@127.0.0.1:5672/aucar: [Errno 111] Connection refused.
Trying again in 12.00 seconds...

[2018-10-14 19:32:38,354: ERROR/MainProcess] consumer: Cannot connect to amqp://aucar:**@127.0.0.1:5672/aucar: [Errno 111] Connection refused.
Trying again in 14.00 seconds...

[2018-10-14 19:32:52,382: ERROR/MainProcess] consumer: Cannot connect to amqp://aucar:**@127.0.0.1:5672/aucar: [Errno 111] Connection refused.
Trying again in 16.00 seconds...

[2018-10-14 19:33:08,413: ERROR/MainProcess] consumer: Cannot connect to amqp://aucar:**@127.0.0.1:5672/aucar: [Errno 111] Connection refused.
Trying again in 18.00 seconds...

[2018-10-14 19:33:26,446: ERROR/MainProcess] consumer: Cannot connect to amqp://aucar:**@127.0.0.1:5672/aucar: [Errno 111] Connection refused.
Trying again in 20.00 seconds...

[2018-10-14 19:33:46,481: ERROR/MainProcess] consumer: Cannot connect to amqp://aucar:**@127.0.0.1:5672/aucar: [Errno 111] Connection refused.
Trying again in 22.00 seconds...

[2018-10-14 19:34:08,520: ERROR/MainProcess] consumer: Cannot connect to amqp://aucar:**@127.0.0.1:5672/aucar: [Errno 111] Connection refused.
Trying again in 24.00 seconds...

[2018-10-14 19:34:32,553: ERROR/MainProcess] consumer: Cannot connect to amqp://aucar:**@127.0.0.1:5672/aucar: [Errno 111] Connection refused.
Trying again in 26.00 seconds...

[2018-10-14 19:34:58,593: ERROR/MainProcess] consumer: Cannot connect to amqp://aucar:**@127.0.0.1:5672/aucar: [Errno 111] Connection refused.
Trying again in 28.00 seconds...

[2018-10-14 19:35:26,635: ERROR/MainProcess] consumer: Cannot connect to amqp://aucar:**@127.0.0.1:5672/aucar: [Errno 111] Connection refused.
Trying again in 30.00 seconds...

[2018-10-14 19:35:56,677: ERROR/MainProcess] consumer: Cannot connect to amqp://aucar:**@127.0.0.1:5672/aucar: [Errno 111] Connection refused.
Trying again in 32.00 seconds...

[2018-10-14 19:36:28,726: ERROR/MainProcess] consumer: Cannot connect to amqp://aucar:**@127.0.0.1:5672/aucar: [Errno 111] Connection refused.
Trying again in 32.00 seconds...

[2018-10-14 19:37:00,772: ERROR/MainProcess] consumer: Cannot connect to amqp://aucar:**@127.0.0.1:5672/aucar: [Errno 111] Connection refused.
Trying again in 32.00 seconds...

[2018-10-14 19:37:32,821: ERROR/MainProcess] consumer: Cannot connect to amqp://aucar:**@127.0.0.1:5672/aucar: [Errno 111] Connection refused.
Trying again in 32.00 seconds...

[2018-10-14 19:38:04,869: ERROR/MainProcess] consumer: Cannot connect to amqp://aucar:**@127.0.0.1:5672/aucar: [Errno 111] Connection refused.
Trying again in 32.00 seconds...

INFO : 2018-10-14 19:38:53,087 : Running with settings
NFS_PATH:/home/nfs
HOST_NAME:localhost
PORT:8000
CLIENT_VIDEO_STATUS_URL:http://${WEB_IP}:${WEB_PORT}/api/contest/videos/status/
Running with settings
NFS_PATH:/home/nfs
HOST_NAME:localhost
PORT:8000
CLIENT_VIDEO_STATUS_URL:http://${WEB_IP}:${WEB_PORT}/api/contest/videos/status/
/usr/local/lib/python3.6/site-packages/celery/platforms.py:796: RuntimeWarning: You're running the worker with superuser privileges: this is
absolutely not recommended!

Please specify a different user using the --uid option.

User information: uid=0 euid=0 gid=0 egid=0

  uid=uid, euid=euid, gid=gid, egid=egid,
[2018-10-14 19:38:53,223: INFO/MainProcess] Connected to amqp://aucar:**@172.17.0.2:5672/aucar
[2018-10-14 19:38:53,258: INFO/MainProcess] mingle: searching for neighbors
[2018-10-14 19:38:54,350: INFO/MainProcess] mingle: all alone
[2018-10-14 19:38:54,376: INFO/MainProcess] celery@1c77dbcf1540 ready.
[2018-10-14 19:38:58,117: INFO/MainProcess] Events of group {task} enabled by remote.
INFO : 2018-10-14 20:16:07,721 : Running with settings
NFS_PATH:	/home/nfs
WEB_IP:	192.168.0.24
WEB_PORT:	8000
WEB_VIDEO_STAT_ENPOINT:	http://${WEB_IP}:${WEB_PORT}/api/contest/videos/status/
Running with settings
NFS_PATH:	/home/nfs
WEB_IP:	192.168.0.24
WEB_PORT:	8000
WEB_VIDEO_STAT_ENPOINT:	http://${WEB_IP}:${WEB_PORT}/api/contest/videos/status/
/usr/local/lib/python3.6/site-packages/celery/platforms.py:796: RuntimeWarning: You're running the worker with superuser privileges: this is
absolutely not recommended!

Please specify a different user using the --uid option.

User information: uid=0 euid=0 gid=0 egid=0

  uid=uid, euid=euid, gid=gid, egid=egid,
[2018-10-14 20:16:07,857: INFO/MainProcess] Connected to amqp://aucar:**@172.17.0.2:5672/aucar
[2018-10-14 20:16:07,877: INFO/MainProcess] mingle: searching for neighbors
[2018-10-14 20:16:08,991: INFO/MainProcess] mingle: all alone
[2018-10-14 20:16:09,021: INFO/MainProcess] celery@3cc660ae9a49 ready.
[2018-10-14 20:16:12,770: INFO/MainProcess] Events of group {task} enabled by remote.
INFO : 2018-10-14 20:23:13,851 : Running with settings
NFS_PATH:	/home/nfs
WEB_IP:	192.168.0.24
WEB_PORT:	8000
WEB_VIDEO_STAT_ENPOINT:	http://${WEB_IP}:${WEB_PORT}/api/contest/videos/status/
Running with settings
NFS_PATH:	/home/nfs
WEB_IP:	192.168.0.24
WEB_PORT:	8000
WEB_VIDEO_STAT_ENPOINT:	http://${WEB_IP}:${WEB_PORT}/api/contest/videos/status/
/usr/local/lib/python3.6/site-packages/celery/platforms.py:796: RuntimeWarning: You're running the worker with superuser privileges: this is
absolutely not recommended!

Please specify a different user using the --uid option.

User information: uid=0 euid=0 gid=0 egid=0

  uid=uid, euid=euid, gid=gid, egid=egid,
[2018-10-14 20:23:13,958: INFO/MainProcess] Connected to amqp://aucar:**@172.17.0.2:5672/aucar
[2018-10-14 20:23:13,991: INFO/MainProcess] mingle: searching for neighbors
[2018-10-14 20:23:15,062: INFO/MainProcess] mingle: all alone
[2018-10-14 20:23:15,097: INFO/MainProcess] celery@3cc660ae9a49 ready.
[2018-10-14 20:23:18,969: INFO/MainProcess] Events of group {task} enabled by remote.
[2018-10-14 20:47:33,445: INFO/MainProcess] Received task: tasks.hello_world[cef6adc2-629c-4fb5-b7a7-c89c2a581e9e]  
/usr/local/lib/python3.6/site-packages/celery/platforms.py:796: RuntimeWarning: You're running the worker with superuser privileges: this is
absolutely not recommended!

Please specify a different user using the --uid option.

User information: uid=0 euid=0 gid=0 egid=0

  uid=uid, euid=euid, gid=gid, egid=egid,
[2018-10-14 20:47:33,465: INFO/ForkPoolWorker-1] Task tasks.hello_world[cef6adc2-629c-4fb5-b7a7-c89c2a581e9e] succeeded in 0.01742387900048925s: 'Hello World'
[2018-10-14 20:52:08,353: INFO/MainProcess] Received task: tasks.task_process_video[d29542d1-fb28-4f23-9a40-0a6ef1e8de05]  
[2018-10-14 20:52:08,373: ERROR/ForkPoolWorker-1] Task tasks.task_process_video[d29542d1-fb28-4f23-9a40-0a6ef1e8de05] raised unexpected: NameError("name 'process_client_video' is not defined",)
Traceback (most recent call last):
  File "/usr/local/lib/python3.6/site-packages/celery/app/trace.py", line 382, in trace_task
    R = retval = fun(*args, **kwargs)
  File "/usr/local/lib/python3.6/site-packages/celery/app/trace.py", line 641, in __protected_call__
    return self.run(*args, **kwargs)
  File "/home/app/tasks.py", line 18, in task_process_video
    return process_client_video(domain_url, video_id, input_file, output_file)
NameError: name 'process_client_video' is not defined
INFO : 2018-10-14 20:58:28,407 : Running with settings
NFS_PATH:	/home/nfs
WEB_IP:	192.168.0.24
WEB_PORT:	8000
WEB_VIDEO_STAT_ENPOINT:	http://${WEB_IP}:${WEB_PORT}/api/contest/videos/status/
Running with settings
NFS_PATH:	/home/nfs
WEB_IP:	192.168.0.24
WEB_PORT:	8000
WEB_VIDEO_STAT_ENPOINT:	http://${WEB_IP}:${WEB_PORT}/api/contest/videos/status/
/usr/local/lib/python3.6/site-packages/celery/platforms.py:796: RuntimeWarning: You're running the worker with superuser privileges: this is
absolutely not recommended!

Please specify a different user using the --uid option.

User information: uid=0 euid=0 gid=0 egid=0

  uid=uid, euid=euid, gid=gid, egid=egid,
[2018-10-14 20:58:28,551: INFO/MainProcess] Connected to amqp://aucar:**@172.17.0.2:5672/aucar
[2018-10-14 20:58:28,572: INFO/MainProcess] mingle: searching for neighbors
[2018-10-14 20:58:29,733: INFO/MainProcess] mingle: all alone
[2018-10-14 20:58:29,751: INFO/MainProcess] celery@a0fac2249c9c ready.
[2018-10-14 20:58:33,441: INFO/MainProcess] Events of group {task} enabled by remote.
[2018-10-14 20:59:03,898: INFO/MainProcess] Received task: tasks.process_video[6805a069-91f1-4ea9-a690-b2298f6bb317]  
/usr/local/lib/python3.6/site-packages/celery/platforms.py:796: RuntimeWarning: You're running the worker with superuser privileges: this is
absolutely not recommended!

Please specify a different user using the --uid option.

User information: uid=0 euid=0 gid=0 egid=0

  uid=uid, euid=euid, gid=gid, egid=egid,
[2018-10-14 20:59:03,919: ERROR/ForkPoolWorker-1] Task tasks.process_video[6805a069-91f1-4ea9-a690-b2298f6bb317] raised unexpected: TypeError("join() argument must be str or bytes, not 'list'",)
Traceback (most recent call last):
  File "/usr/local/lib/python3.6/site-packages/celery/app/trace.py", line 382, in trace_task
    R = retval = fun(*args, **kwargs)
  File "/usr/local/lib/python3.6/site-packages/celery/app/trace.py", line 641, in __protected_call__
    return self.run(*args, **kwargs)
  File "/home/app/tasks.py", line 18, in process_video
    return process_client_video(domain_url, video_id, input_file, output_file)
  File "/home/app/processing.py", line 121, in process_client_video
    code, out, err = process_video(input_file,output_file)
  File "/home/app/processing.py", line 61, in process_video
    input_file = os.path.join(NFS_PATH,input_file)
  File "/usr/local/lib/python3.6/posixpath.py", line 94, in join
    genericpath._check_arg_types('join', a, *p)
  File "/usr/local/lib/python3.6/genericpath.py", line 149, in _check_arg_types
    (funcname, s.__class__.__name__)) from None
TypeError: join() argument must be str or bytes, not 'list'
[2018-10-14 21:03:29,923: INFO/MainProcess] Received task: tasks.process_video[873326e3-4d8a-4f37-9337-0e285359f7e9]  
[2018-10-14 21:03:29,943: ERROR/ForkPoolWorker-1] Task tasks.process_video[873326e3-4d8a-4f37-9337-0e285359f7e9] raised unexpected: TypeError("join() argument must be str or bytes, not 'list'",)
Traceback (most recent call last):
  File "/usr/local/lib/python3.6/site-packages/celery/app/trace.py", line 382, in trace_task
    R = retval = fun(*args, **kwargs)
  File "/usr/local/lib/python3.6/site-packages/celery/app/trace.py", line 641, in __protected_call__
    return self.run(*args, **kwargs)
  File "/home/app/tasks.py", line 18, in process_video
    return process_client_video(domain_url, video_id, input_file, output_file)
  File "/home/app/processing.py", line 121, in process_client_video
    code, out, err = process_video(input_file,output_file)
  File "/home/app/processing.py", line 61, in process_video
    input_file = os.path.join(NFS_PATH,input_file)
  File "/usr/local/lib/python3.6/posixpath.py", line 94, in join
    genericpath._check_arg_types('join', a, *p)
  File "/usr/local/lib/python3.6/genericpath.py", line 149, in _check_arg_types
    (funcname, s.__class__.__name__)) from None
TypeError: join() argument must be str or bytes, not 'list'
[2018-10-14 21:04:42,691: INFO/MainProcess] Received task: tasks.process_video[be2366ef-6747-488c-8175-51101179e80d]  
[2018-10-14 21:04:42,694: ERROR/ForkPoolWorker-1] Task tasks.process_video[be2366ef-6747-488c-8175-51101179e80d] raised unexpected: TypeError("join() argument must be str or bytes, not 'list'",)
Traceback (most recent call last):
  File "/usr/local/lib/python3.6/site-packages/celery/app/trace.py", line 382, in trace_task
    R = retval = fun(*args, **kwargs)
  File "/usr/local/lib/python3.6/site-packages/celery/app/trace.py", line 641, in __protected_call__
    return self.run(*args, **kwargs)
  File "/home/app/tasks.py", line 18, in process_video
    return process_client_video(domain_url, video_id, input_file, output_file)
  File "/home/app/processing.py", line 121, in process_client_video
    code, out, err = process_video(input_file,output_file)
  File "/home/app/processing.py", line 61, in process_video
    input_file = os.path.join(NFS_PATH,input_file)
  File "/usr/local/lib/python3.6/posixpath.py", line 94, in join
    genericpath._check_arg_types('join', a, *p)
  File "/usr/local/lib/python3.6/genericpath.py", line 149, in _check_arg_types
    (funcname, s.__class__.__name__)) from None
TypeError: join() argument must be str or bytes, not 'list'
[2018-10-14 21:40:26,434: INFO/MainProcess] Received task: tasks.process_video[e0a0fc03-0f5a-4272-a958-70e99bf315fc]  
[2018-10-14 21:40:26,453: ERROR/ForkPoolWorker-1] Task tasks.process_video[e0a0fc03-0f5a-4272-a958-70e99bf315fc] raised unexpected: TypeError("join() argument must be str or bytes, not 'list'",)
Traceback (most recent call last):
  File "/usr/local/lib/python3.6/site-packages/celery/app/trace.py", line 382, in trace_task
    R = retval = fun(*args, **kwargs)
  File "/usr/local/lib/python3.6/site-packages/celery/app/trace.py", line 641, in __protected_call__
    return self.run(*args, **kwargs)
  File "/home/app/tasks.py", line 18, in process_video
    return process_client_video(domain_url, video_id, input_file, output_file)
  File "/home/app/processing.py", line 121, in process_client_video
    code, out, err = process_video(input_file,output_file)
  File "/home/app/processing.py", line 61, in process_video
    input_file = os.path.join(NFS_PATH,input_file)
  File "/usr/local/lib/python3.6/posixpath.py", line 94, in join
    genericpath._check_arg_types('join', a, *p)
  File "/usr/local/lib/python3.6/genericpath.py", line 149, in _check_arg_types
    (funcname, s.__class__.__name__)) from None
TypeError: join() argument must be str or bytes, not 'list'
[2018-10-14 21:44:09,749: INFO/MainProcess] Received task: tasks.process_video[387e8963-7b14-4b58-8d51-5d73906b2174]  
[2018-10-14 21:44:09,750: INFO/ForkPoolWorker-1] Start processing /home/nfs/nput_file to /home/nfs/utput_file
[2018-10-14 21:44:10,336: ERROR/ForkPoolWorker-1]  ffmpeg version 3.2.12-1~deb9u1 Copyright (c) 2000-2018 the FFmpeg developers
  built with gcc 6.3.0 (Debian 6.3.0-18+deb9u1) 20170516
  configuration: --prefix=/usr --extra-version='1~deb9u1' --toolchain=hardened --libdir=/usr/lib/x86_64-linux-gnu --incdir=/usr/include/x86_64-linux-gnu --enable-gpl --disable-stripping --enable-avresample --enable-avisynth --enable-gnutls --enable-ladspa --enable-libass --enable-libbluray --enable-libbs2b --enable-libcaca --enable-libcdio --enable-libebur128 --enable-libflite --enable-libfontconfig --enable-libfreetype --enable-libfribidi --enable-libgme --enable-libgsm --enable-libmp3lame --enable-libopenjpeg --enable-libopenmpt --enable-libopus --enable-libpulse --enable-librubberband --enable-libshine --enable-libsnappy --enable-libsoxr --enable-libspeex --enable-libssh --enable-libtheora --enable-libtwolame --enable-libvorbis --enable-libvpx --enable-libwavpack --enable-libwebp --enable-libx265 --enable-libxvid --enable-libzmq --enable-libzvbi --enable-omx --enable-openal --enable-opengl --enable-sdl2 --enable-libdc1394 --enable-libiec61883 --enable-chromaprint --enable-frei0r --enable-libopencv --enable-libx264 --enable-shared
  libavutil      55. 34.101 / 55. 34.101
  libavcodec     57. 64.101 / 57. 64.101
  libavformat    57. 56.101 / 57. 56.101
  libavdevice    57.  1.100 / 57.  1.100
  libavfilter     6. 65.100 /  6. 65.100
  libavresample   3.  1.  0 /  3.  1.  0
  libswscale      4.  2.100 /  4.  2.100
  libswresample   2.  3.100 /  2.  3.100
  libpostproc    54.  1.100 / 54.  1.100
/home/nfs/nput_file: No such file or directory
 /home/nfs/nput_file
[2018-10-14 21:44:10,337: ERROR/ForkPoolWorker-1]  ffmpeg version 3.2.12-1~deb9u1 Copyright (c) 2000-2018 the FFmpeg developers
  built with gcc 6.3.0 (Debian 6.3.0-18+deb9u1) 20170516
  configuration: --prefix=/usr --extra-version='1~deb9u1' --toolchain=hardened --libdir=/usr/lib/x86_64-linux-gnu --incdir=/usr/include/x86_64-linux-gnu --enable-gpl --disable-stripping --enable-avresample --enable-avisynth --enable-gnutls --enable-ladspa --enable-libass --enable-libbluray --enable-libbs2b --enable-libcaca --enable-libcdio --enable-libebur128 --enable-libflite --enable-libfontconfig --enable-libfreetype --enable-libfribidi --enable-libgme --enable-libgsm --enable-libmp3lame --enable-libopenjpeg --enable-libopenmpt --enable-libopus --enable-libpulse --enable-librubberband --enable-libshine --enable-libsnappy --enable-libsoxr --enable-libspeex --enable-libssh --enable-libtheora --enable-libtwolame --enable-libvorbis --enable-libvpx --enable-libwavpack --enable-libwebp --enable-libx265 --enable-libxvid --enable-libzmq --enable-libzvbi --enable-omx --enable-openal --enable-opengl --enable-sdl2 --enable-libdc1394 --enable-libiec61883 --enable-chromaprint --enable-frei0r --enable-libopencv --enable-libx264 --enable-shared
  libavutil      55. 34.101 / 55. 34.101
  libavcodec     57. 64.101 / 57. 64.101
  libavformat    57. 56.101 / 57. 56.101
  libavdevice    57.  1.100 / 57.  1.100
  libavfilter     6. 65.100 /  6. 65.100
  libavresample   3.  1.  0 /  3.  1.  0
  libswscale      4.  2.100 /  4.  2.100
  libswresample   2.  3.100 /  2.  3.100
  libpostproc    54.  1.100 / 54.  1.100
/home/nfs/nput_file: No such file or directory
 input_file
[2018-10-14 21:44:10,355: INFO/ForkPoolWorker-1] Task tasks.process_video[387e8963-7b14-4b58-8d51-5d73906b2174] succeeded in 0.6042569220007863s: 1
[2018-10-14 21:48:13,240: INFO/MainProcess] Received task: tasks.process_video[fe58631c-f43f-4ccf-8cb8-f5e4c6e2405e]  
[2018-10-14 21:48:13,242: INFO/ForkPoolWorker-1] Start processing /home/nfs/'/media/contests/videos/worker1_QNizFIi.webm',) to /home/nfs/media/contests/videos/worker1_QNizFIi._Converted.mp4
[2018-10-14 21:48:13,246: ERROR/ForkPoolWorker-1]  /bin/sh: 1: Syntax error: ")" unexpected
 /home/nfs/'/media/contests/videos/worker1_QNizFIi.webm',)
[2018-10-14 21:48:13,246: ERROR/ForkPoolWorker-1]  /bin/sh: 1: Syntax error: ")" unexpected
 ('/media/contests/videos/worker1_QNizFIi.webm',)
[2018-10-14 21:48:13,260: INFO/ForkPoolWorker-1] Task tasks.process_video[fe58631c-f43f-4ccf-8cb8-f5e4c6e2405e] succeeded in 0.017746898000041256s: 2
[2018-10-14 21:57:39,446: INFO/MainProcess] Received task: tasks.process_video[b92bc169-09e7-4327-8bc2-b170817523cb]  
[2018-10-14 21:57:39,447: INFO/ForkPoolWorker-1] Start processing /home/nfs/'/media/contests/videos/Invencible_QdCeq1O.avi',) to /home/nfs/media/contests/videos/Invencible_QdCeq1O_Converted.mp4
[2018-10-14 21:57:39,450: ERROR/ForkPoolWorker-1]  /bin/sh: 1: Syntax error: ")" unexpected
 /home/nfs/'/media/contests/videos/Invencible_QdCeq1O.avi',)
[2018-10-14 21:57:39,451: ERROR/ForkPoolWorker-1]  /bin/sh: 1: Syntax error: ")" unexpected
 ('/media/contests/videos/Invencible_QdCeq1O.avi',)
[2018-10-14 21:57:39,467: INFO/ForkPoolWorker-1] Task tasks.process_video[b92bc169-09e7-4327-8bc2-b170817523cb] succeeded in 0.020395647999976063s: 2
[2018-10-14 21:59:04,620: INFO/MainProcess] Received task: tasks.process_video[c260b036-e4c8-44b0-8d99-5ae6c97b3e15]  
[2018-10-14 21:59:04,624: ERROR/ForkPoolWorker-1] Task tasks.process_video[c260b036-e4c8-44b0-8d99-5ae6c97b3e15] raised unexpected: TypeError("join() argument must be str or bytes, not 'list'",)
Traceback (most recent call last):
  File "/usr/local/lib/python3.6/site-packages/celery/app/trace.py", line 382, in trace_task
    R = retval = fun(*args, **kwargs)
  File "/usr/local/lib/python3.6/site-packages/celery/app/trace.py", line 641, in __protected_call__
    return self.run(*args, **kwargs)
  File "/home/app/tasks.py", line 18, in process_video
    return process_client_video(domain_url, video_id, input_file, output_file)
  File "/home/app/processing.py", line 121, in process_client_video
    code, out, err = process_video(input_file,output_file)
  File "/home/app/processing.py", line 61, in process_video
    input_file = os.path.join(NFS_PATH,input_file)
  File "/usr/local/lib/python3.6/posixpath.py", line 94, in join
    genericpath._check_arg_types('join', a, *p)
  File "/usr/local/lib/python3.6/genericpath.py", line 149, in _check_arg_types
    (funcname, s.__class__.__name__)) from None
TypeError: join() argument must be str or bytes, not 'list'
[2018-10-14 22:28:56,428: INFO/MainProcess] Received task: tasks.process_video[30401df6-00da-4928-8297-a93dfa200049]  
[2018-10-14 22:28:56,445: ERROR/ForkPoolWorker-1] Task tasks.process_video[30401df6-00da-4928-8297-a93dfa200049] raised unexpected: TypeError("join() argument must be str or bytes, not 'list'",)
Traceback (most recent call last):
  File "/usr/local/lib/python3.6/site-packages/celery/app/trace.py", line 382, in trace_task
    R = retval = fun(*args, **kwargs)
  File "/usr/local/lib/python3.6/site-packages/celery/app/trace.py", line 641, in __protected_call__
    return self.run(*args, **kwargs)
  File "/home/app/tasks.py", line 18, in process_video
    return process_client_video(domain_url, video_id, input_file, output_file)
  File "/home/app/processing.py", line 121, in process_client_video
    code, out, err = process_video(input_file,output_file)
  File "/home/app/processing.py", line 61, in process_video
    input_file = os.path.join(NFS_PATH,input_file)
  File "/usr/local/lib/python3.6/posixpath.py", line 94, in join
    genericpath._check_arg_types('join', a, *p)
  File "/usr/local/lib/python3.6/genericpath.py", line 149, in _check_arg_types
    (funcname, s.__class__.__name__)) from None
TypeError: join() argument must be str or bytes, not 'list'
[2018-10-14 22:36:39,908: INFO/MainProcess] Received task: tasks.process_video[2de494de-cc1a-488c-9d11-9339d1146e0b]  
[2018-10-14 22:36:39,925: ERROR/ForkPoolWorker-1] Task tasks.process_video[2de494de-cc1a-488c-9d11-9339d1146e0b] raised unexpected: TypeError("join() argument must be str or bytes, not 'list'",)
Traceback (most recent call last):
  File "/usr/local/lib/python3.6/site-packages/celery/app/trace.py", line 382, in trace_task
    R = retval = fun(*args, **kwargs)
  File "/usr/local/lib/python3.6/site-packages/celery/app/trace.py", line 641, in __protected_call__
    return self.run(*args, **kwargs)
  File "/home/app/tasks.py", line 18, in process_video
    return process_client_video(domain_url, video_id, input_file, output_file)
  File "/home/app/processing.py", line 121, in process_client_video
    code, out, err = process_video(input_file,output_file)
  File "/home/app/processing.py", line 61, in process_video
    input_file = os.path.join(NFS_PATH,input_file)
  File "/usr/local/lib/python3.6/posixpath.py", line 94, in join
    genericpath._check_arg_types('join', a, *p)
  File "/usr/local/lib/python3.6/genericpath.py", line 149, in _check_arg_types
    (funcname, s.__class__.__name__)) from None
TypeError: join() argument must be str or bytes, not 'list'
[2018-10-14 22:41:51,710: INFO/MainProcess] Received task: tasks.process_video[8cf2cb3c-1cd8-4f95-b2d3-81a159ebaa4f]  
[2018-10-14 22:41:51,730: ERROR/ForkPoolWorker-1] Task tasks.process_video[8cf2cb3c-1cd8-4f95-b2d3-81a159ebaa4f] raised unexpected: TypeError("join() argument must be str or bytes, not 'list'",)
Traceback (most recent call last):
  File "/usr/local/lib/python3.6/site-packages/celery/app/trace.py", line 382, in trace_task
    R = retval = fun(*args, **kwargs)
  File "/usr/local/lib/python3.6/site-packages/celery/app/trace.py", line 641, in __protected_call__
    return self.run(*args, **kwargs)
  File "/home/app/tasks.py", line 18, in process_video
    return process_client_video(domain_url, video_id, input_file, output_file)
  File "/home/app/processing.py", line 121, in process_client_video
    code, out, err = process_video(input_file,output_file)
  File "/home/app/processing.py", line 61, in process_video
    input_file = os.path.join(NFS_PATH,input_file)
  File "/usr/local/lib/python3.6/posixpath.py", line 94, in join
    genericpath._check_arg_types('join', a, *p)
  File "/usr/local/lib/python3.6/genericpath.py", line 149, in _check_arg_types
    (funcname, s.__class__.__name__)) from None
TypeError: join() argument must be str or bytes, not 'list'
[2018-10-14 22:42:24,147: INFO/MainProcess] Received task: tasks.process_video[0c171818-0fda-4495-8a97-e2c9597a655c]  
[2018-10-14 22:42:24,150: ERROR/ForkPoolWorker-1] Task tasks.process_video[0c171818-0fda-4495-8a97-e2c9597a655c] raised unexpected: TypeError("join() argument must be str or bytes, not 'list'",)
Traceback (most recent call last):
  File "/usr/local/lib/python3.6/site-packages/celery/app/trace.py", line 382, in trace_task
    R = retval = fun(*args, **kwargs)
  File "/usr/local/lib/python3.6/site-packages/celery/app/trace.py", line 641, in __protected_call__
    return self.run(*args, **kwargs)
  File "/home/app/tasks.py", line 18, in process_video
    return process_client_video(domain_url, video_id, input_file, output_file)
  File "/home/app/processing.py", line 121, in process_client_video
    code, out, err = process_video(input_file,output_file)
  File "/home/app/processing.py", line 61, in process_video
    input_file = os.path.join(NFS_PATH,input_file)
  File "/usr/local/lib/python3.6/posixpath.py", line 94, in join
    genericpath._check_arg_types('join', a, *p)
  File "/usr/local/lib/python3.6/genericpath.py", line 149, in _check_arg_types
    (funcname, s.__class__.__name__)) from None
TypeError: join() argument must be str or bytes, not 'list'
[2018-10-14 22:42:55,205: INFO/MainProcess] Received task: tasks.process_video[5c91f5bc-3f24-43cf-997c-c35b517b5301]  
[2018-10-14 22:42:55,208: ERROR/ForkPoolWorker-1] Task tasks.process_video[5c91f5bc-3f24-43cf-997c-c35b517b5301] raised unexpected: TypeError("join() argument must be str or bytes, not 'list'",)
Traceback (most recent call last):
  File "/usr/local/lib/python3.6/site-packages/celery/app/trace.py", line 382, in trace_task
    R = retval = fun(*args, **kwargs)
  File "/usr/local/lib/python3.6/site-packages/celery/app/trace.py", line 641, in __protected_call__
    return self.run(*args, **kwargs)
  File "/home/app/tasks.py", line 18, in process_video
    return process_client_video(domain_url, video_id, input_file, output_file)
  File "/home/app/processing.py", line 121, in process_client_video
    code, out, err = process_video(input_file,output_file)
  File "/home/app/processing.py", line 61, in process_video
    input_file = os.path.join(NFS_PATH,input_file)
  File "/usr/local/lib/python3.6/posixpath.py", line 94, in join
    genericpath._check_arg_types('join', a, *p)
  File "/usr/local/lib/python3.6/genericpath.py", line 149, in _check_arg_types
    (funcname, s.__class__.__name__)) from None
TypeError: join() argument must be str or bytes, not 'list'
[2018-10-14 22:55:54,296: INFO/MainProcess] Received task: tasks.process_video[24576ad2-5d9e-4d43-ac1f-f1a6f2af0077]  
[2018-10-14 22:55:54,331: INFO/ForkPoolWorker-1] Start processing /home/nfs/'/media/contests/videos/Video2_dO4qWjy.avi',) to /media/contests/videos/Video2_dO4qWjy_Converted.mp4'
[2018-10-14 22:55:54,337: ERROR/ForkPoolWorker-1]  /bin/sh: 1: Syntax error: ")" unexpected
 /home/nfs/'/media/contests/videos/Video2_dO4qWjy.avi',)
[2018-10-14 22:55:54,337: ERROR/ForkPoolWorker-1]  /bin/sh: 1: Syntax error: ")" unexpected
 ('/media/contests/videos/Video2_dO4qWjy.avi',)
[2018-10-14 22:55:54,372: INFO/ForkPoolWorker-1] Task tasks.process_video[24576ad2-5d9e-4d43-ac1f-f1a6f2af0077] succeeded in 0.07474379999985103s: 2
[2018-10-14 23:00:38,279: INFO/MainProcess] Received task: tasks.process_video[27c83b95-49dc-4f75-a2ab-3150cf49900d]  
[2018-10-14 23:00:38,281: INFO/ForkPoolWorker-1] Start processing /home/nfs/'/media/contests/videos/worker1_T7UIwVO.webm',) to /media/contests/videos/worker1_T7UIwVO._Converted.mp4'
[2018-10-14 23:00:38,329: ERROR/ForkPoolWorker-1]  /bin/sh: 1: Syntax error: ")" unexpected
 /home/nfs/'/media/contests/videos/worker1_T7UIwVO.webm',)
[2018-10-14 23:00:38,329: ERROR/ForkPoolWorker-1]  /bin/sh: 1: Syntax error: ")" unexpected
 ('/media/contests/videos/worker1_T7UIwVO.webm',)
[2018-10-14 23:00:38,348: INFO/ForkPoolWorker-1] Task tasks.process_video[27c83b95-49dc-4f75-a2ab-3150cf49900d] succeeded in 0.06662950299869408s: 2
[2018-10-14 23:04:30,240: INFO/MainProcess] Received task: tasks.process_video[f332a1e6-5911-4a63-bfa7-af50d24ac9d6]  
[2018-10-14 23:04:30,256: ERROR/ForkPoolWorker-1] Task tasks.process_video[f332a1e6-5911-4a63-bfa7-af50d24ac9d6] raised unexpected: TypeError("join() argument must be str or bytes, not 'list'",)
Traceback (most recent call last):
  File "/usr/local/lib/python3.6/site-packages/celery/app/trace.py", line 382, in trace_task
    R = retval = fun(*args, **kwargs)
  File "/usr/local/lib/python3.6/site-packages/celery/app/trace.py", line 641, in __protected_call__
    return self.run(*args, **kwargs)
  File "/home/app/tasks.py", line 18, in process_video
    return process_client_video(domain_url, video_id, input_file, output_file)
  File "/home/app/processing.py", line 121, in process_client_video
    code, out, err = process_video(input_file,output_file)
  File "/home/app/processing.py", line 61, in process_video
    input_file = os.path.join(NFS_PATH,input_file)
  File "/usr/local/lib/python3.6/posixpath.py", line 94, in join
    genericpath._check_arg_types('join', a, *p)
  File "/usr/local/lib/python3.6/genericpath.py", line 149, in _check_arg_types
    (funcname, s.__class__.__name__)) from None
TypeError: join() argument must be str or bytes, not 'list'
[2018-10-14 23:06:16,912: INFO/MainProcess] Received task: tasks.process_video[f94e94ef-72ad-4fa9-ad67-0ce8574195ac]  
[2018-10-14 23:06:16,915: ERROR/ForkPoolWorker-1] Task tasks.process_video[f94e94ef-72ad-4fa9-ad67-0ce8574195ac] raised unexpected: TypeError("'int' object is not subscriptable",)
Traceback (most recent call last):
  File "/usr/local/lib/python3.6/site-packages/celery/app/trace.py", line 382, in trace_task
    R = retval = fun(*args, **kwargs)
  File "/usr/local/lib/python3.6/site-packages/celery/app/trace.py", line 641, in __protected_call__
    return self.run(*args, **kwargs)
  File "/home/app/tasks.py", line 18, in process_video
    return process_client_video(domain_url, video_id, input_file, output_file)
  File "/home/app/processing.py", line 121, in process_client_video
    code, out, err = process_video(input_file,output_file)
  File "/home/app/processing.py", line 58, in process_video
    input_file = input_file[1:]
TypeError: 'int' object is not subscriptable
Traceback (most recent call last):
  File "/usr/local/bin/celery", line 11, in <module>
    sys.exit(main())
  File "/usr/local/lib/python3.6/site-packages/celery/__main__.py", line 16, in main
    _main()
  File "/usr/local/lib/python3.6/site-packages/celery/bin/celery.py", line 322, in main
    cmd.execute_from_commandline(argv)
  File "/usr/local/lib/python3.6/site-packages/celery/bin/celery.py", line 496, in execute_from_commandline
    super(CeleryCommand, self).execute_from_commandline(argv)))
  File "/usr/local/lib/python3.6/site-packages/celery/bin/base.py", line 273, in execute_from_commandline
    argv = self.setup_app_from_commandline(argv)
  File "/usr/local/lib/python3.6/site-packages/celery/bin/base.py", line 479, in setup_app_from_commandline
    self.app = self.find_app(app)
  File "/usr/local/lib/python3.6/site-packages/celery/bin/base.py", line 501, in find_app
    return find_app(app, symbol_by_name=self.symbol_by_name)
  File "/usr/local/lib/python3.6/site-packages/celery/app/utils.py", line 359, in find_app
    sym = symbol_by_name(app, imp=imp)
  File "/usr/local/lib/python3.6/site-packages/celery/bin/base.py", line 504, in symbol_by_name
    return imports.symbol_by_name(name, imp=imp)
  File "/usr/local/lib/python3.6/site-packages/kombu/utils/imports.py", line 56, in symbol_by_name
    module = imp(module_name, package=package, **kwargs)
  File "/usr/local/lib/python3.6/site-packages/celery/utils/imports.py", line 104, in import_from_cwd
    return imp(module, package=package)
  File "/usr/local/lib/python3.6/importlib/__init__.py", line 126, in import_module
    return _bootstrap._gcd_import(name[level:], package, level)
  File "<frozen importlib._bootstrap>", line 994, in _gcd_import
  File "<frozen importlib._bootstrap>", line 971, in _find_and_load
  File "<frozen importlib._bootstrap>", line 955, in _find_and_load_unlocked
  File "<frozen importlib._bootstrap>", line 665, in _load_unlocked
  File "<frozen importlib._bootstrap_external>", line 674, in exec_module
  File "<frozen importlib._bootstrap_external>", line 781, in get_code
  File "<frozen importlib._bootstrap_external>", line 741, in source_to_code
  File "<frozen importlib._bootstrap>", line 219, in _call_with_frames_removed
  File "/home/app/tasks.py", line 21
    return process_client_video(domain_url, video_id, input_file, output_file)
                                                                             ^
IndentationError: unindent does not match any outer indentation level
Traceback (most recent call last):
  File "/usr/local/bin/celery", line 11, in <module>
    sys.exit(main())
  File "/usr/local/lib/python3.6/site-packages/celery/__main__.py", line 16, in main
    _main()
  File "/usr/local/lib/python3.6/site-packages/celery/bin/celery.py", line 322, in main
    cmd.execute_from_commandline(argv)
  File "/usr/local/lib/python3.6/site-packages/celery/bin/celery.py", line 496, in execute_from_commandline
    super(CeleryCommand, self).execute_from_commandline(argv)))
  File "/usr/local/lib/python3.6/site-packages/celery/bin/base.py", line 273, in execute_from_commandline
    argv = self.setup_app_from_commandline(argv)
  File "/usr/local/lib/python3.6/site-packages/celery/bin/base.py", line 479, in setup_app_from_commandline
    self.app = self.find_app(app)
  File "/usr/local/lib/python3.6/site-packages/celery/bin/base.py", line 501, in find_app
    return find_app(app, symbol_by_name=self.symbol_by_name)
  File "/usr/local/lib/python3.6/site-packages/celery/app/utils.py", line 359, in find_app
    sym = symbol_by_name(app, imp=imp)
  File "/usr/local/lib/python3.6/site-packages/celery/bin/base.py", line 504, in symbol_by_name
    return imports.symbol_by_name(name, imp=imp)
  File "/usr/local/lib/python3.6/site-packages/kombu/utils/imports.py", line 56, in symbol_by_name
    module = imp(module_name, package=package, **kwargs)
  File "/usr/local/lib/python3.6/site-packages/celery/utils/imports.py", line 104, in import_from_cwd
    return imp(module, package=package)
  File "/usr/local/lib/python3.6/importlib/__init__.py", line 126, in import_module
    return _bootstrap._gcd_import(name[level:], package, level)
  File "<frozen importlib._bootstrap>", line 994, in _gcd_import
  File "<frozen importlib._bootstrap>", line 971, in _find_and_load
  File "<frozen importlib._bootstrap>", line 955, in _find_and_load_unlocked
  File "<frozen importlib._bootstrap>", line 665, in _load_unlocked
  File "<frozen importlib._bootstrap_external>", line 674, in exec_module
  File "<frozen importlib._bootstrap_external>", line 781, in get_code
  File "<frozen importlib._bootstrap_external>", line 741, in source_to_code
  File "<frozen importlib._bootstrap>", line 219, in _call_with_frames_removed
  File "/home/app/tasks.py", line 21
    return process_client_video(domain_url, video_id, input_file, output_file)
                                                                             ^
IndentationError: unindent does not match any outer indentation level
Traceback (most recent call last):
  File "/usr/local/bin/celery", line 11, in <module>
    sys.exit(main())
  File "/usr/local/lib/python3.6/site-packages/celery/__main__.py", line 16, in main
    _main()
  File "/usr/local/lib/python3.6/site-packages/celery/bin/celery.py", line 322, in main
    cmd.execute_from_commandline(argv)
  File "/usr/local/lib/python3.6/site-packages/celery/bin/celery.py", line 496, in execute_from_commandline
    super(CeleryCommand, self).execute_from_commandline(argv)))
  File "/usr/local/lib/python3.6/site-packages/celery/bin/base.py", line 273, in execute_from_commandline
    argv = self.setup_app_from_commandline(argv)
  File "/usr/local/lib/python3.6/site-packages/celery/bin/base.py", line 479, in setup_app_from_commandline
    self.app = self.find_app(app)
  File "/usr/local/lib/python3.6/site-packages/celery/bin/base.py", line 501, in find_app
    return find_app(app, symbol_by_name=self.symbol_by_name)
  File "/usr/local/lib/python3.6/site-packages/celery/app/utils.py", line 359, in find_app
    sym = symbol_by_name(app, imp=imp)
  File "/usr/local/lib/python3.6/site-packages/celery/bin/base.py", line 504, in symbol_by_name
    return imports.symbol_by_name(name, imp=imp)
  File "/usr/local/lib/python3.6/site-packages/kombu/utils/imports.py", line 56, in symbol_by_name
    module = imp(module_name, package=package, **kwargs)
  File "/usr/local/lib/python3.6/site-packages/celery/utils/imports.py", line 104, in import_from_cwd
    return imp(module, package=package)
  File "/usr/local/lib/python3.6/importlib/__init__.py", line 126, in import_module
    return _bootstrap._gcd_import(name[level:], package, level)
  File "<frozen importlib._bootstrap>", line 994, in _gcd_import
  File "<frozen importlib._bootstrap>", line 971, in _find_and_load
  File "<frozen importlib._bootstrap>", line 955, in _find_and_load_unlocked
  File "<frozen importlib._bootstrap>", line 665, in _load_unlocked
  File "<frozen importlib._bootstrap_external>", line 674, in exec_module
  File "<frozen importlib._bootstrap_external>", line 781, in get_code
  File "<frozen importlib._bootstrap_external>", line 741, in source_to_code
  File "<frozen importlib._bootstrap>", line 219, in _call_with_frames_removed
  File "/home/app/tasks.py", line 21
    return process_client_video(domain_url, video_id, input_file, output_file)
                                                                             ^
IndentationError: unindent does not match any outer indentation level
Traceback (most recent call last):
  File "/usr/local/bin/celery", line 11, in <module>
    sys.exit(main())
  File "/usr/local/lib/python3.6/site-packages/celery/__main__.py", line 16, in main
    _main()
  File "/usr/local/lib/python3.6/site-packages/celery/bin/celery.py", line 322, in main
    cmd.execute_from_commandline(argv)
  File "/usr/local/lib/python3.6/site-packages/celery/bin/celery.py", line 496, in execute_from_commandline
    super(CeleryCommand, self).execute_from_commandline(argv)))
  File "/usr/local/lib/python3.6/site-packages/celery/bin/base.py", line 273, in execute_from_commandline
    argv = self.setup_app_from_commandline(argv)
  File "/usr/local/lib/python3.6/site-packages/celery/bin/base.py", line 479, in setup_app_from_commandline
    self.app = self.find_app(app)
  File "/usr/local/lib/python3.6/site-packages/celery/bin/base.py", line 501, in find_app
    return find_app(app, symbol_by_name=self.symbol_by_name)
  File "/usr/local/lib/python3.6/site-packages/celery/app/utils.py", line 359, in find_app
    sym = symbol_by_name(app, imp=imp)
  File "/usr/local/lib/python3.6/site-packages/celery/bin/base.py", line 504, in symbol_by_name
    return imports.symbol_by_name(name, imp=imp)
  File "/usr/local/lib/python3.6/site-packages/kombu/utils/imports.py", line 56, in symbol_by_name
    module = imp(module_name, package=package, **kwargs)
  File "/usr/local/lib/python3.6/site-packages/celery/utils/imports.py", line 104, in import_from_cwd
    return imp(module, package=package)
  File "/usr/local/lib/python3.6/importlib/__init__.py", line 126, in import_module
    return _bootstrap._gcd_import(name[level:], package, level)
  File "<frozen importlib._bootstrap>", line 994, in _gcd_import
  File "<frozen importlib._bootstrap>", line 971, in _find_and_load
  File "<frozen importlib._bootstrap>", line 955, in _find_and_load_unlocked
  File "<frozen importlib._bootstrap>", line 665, in _load_unlocked
  File "<frozen importlib._bootstrap_external>", line 674, in exec_module
  File "<frozen importlib._bootstrap_external>", line 781, in get_code
  File "<frozen importlib._bootstrap_external>", line 741, in source_to_code
  File "<frozen importlib._bootstrap>", line 219, in _call_with_frames_removed
  File "/home/app/tasks.py", line 21
    return process_client_video(domain_url, video_id, input_file, output_file)
                                                                             ^
IndentationError: unindent does not match any outer indentation level
Traceback (most recent call last):
  File "/usr/local/bin/celery", line 11, in <module>
    sys.exit(main())
  File "/usr/local/lib/python3.6/site-packages/celery/__main__.py", line 16, in main
    _main()
  File "/usr/local/lib/python3.6/site-packages/celery/bin/celery.py", line 322, in main
    cmd.execute_from_commandline(argv)
  File "/usr/local/lib/python3.6/site-packages/celery/bin/celery.py", line 496, in execute_from_commandline
    super(CeleryCommand, self).execute_from_commandline(argv)))
  File "/usr/local/lib/python3.6/site-packages/celery/bin/base.py", line 273, in execute_from_commandline
    argv = self.setup_app_from_commandline(argv)
  File "/usr/local/lib/python3.6/site-packages/celery/bin/base.py", line 479, in setup_app_from_commandline
    self.app = self.find_app(app)
  File "/usr/local/lib/python3.6/site-packages/celery/bin/base.py", line 501, in find_app
    return find_app(app, symbol_by_name=self.symbol_by_name)
  File "/usr/local/lib/python3.6/site-packages/celery/app/utils.py", line 359, in find_app
    sym = symbol_by_name(app, imp=imp)
  File "/usr/local/lib/python3.6/site-packages/celery/bin/base.py", line 504, in symbol_by_name
    return imports.symbol_by_name(name, imp=imp)
  File "/usr/local/lib/python3.6/site-packages/kombu/utils/imports.py", line 56, in symbol_by_name
    module = imp(module_name, package=package, **kwargs)
  File "/usr/local/lib/python3.6/site-packages/celery/utils/imports.py", line 104, in import_from_cwd
    return imp(module, package=package)
  File "/usr/local/lib/python3.6/importlib/__init__.py", line 126, in import_module
    return _bootstrap._gcd_import(name[level:], package, level)
  File "<frozen importlib._bootstrap>", line 994, in _gcd_import
  File "<frozen importlib._bootstrap>", line 971, in _find_and_load
  File "<frozen importlib._bootstrap>", line 955, in _find_and_load_unlocked
  File "<frozen importlib._bootstrap>", line 665, in _load_unlocked
  File "<frozen importlib._bootstrap_external>", line 674, in exec_module
  File "<frozen importlib._bootstrap_external>", line 781, in get_code
  File "<frozen importlib._bootstrap_external>", line 741, in source_to_code
  File "<frozen importlib._bootstrap>", line 219, in _call_with_frames_removed
  File "/home/app/tasks.py", line 21
    return process_client_video(domain_url, video_id, input_file, output_file)
                                                                             ^
IndentationError: unindent does not match any outer indentation level
INFO : 2018-10-14 23:17:21,375 : Running with settings
NFS_PATH:	/home/nfs
WEB_IP:	192.168.0.24
WEB_PORT:	8000
WEB_VIDEO_STAT_ENPOINT:	http://${WEB_IP}:${WEB_PORT}/api/contest/videos/status/
Running with settings
NFS_PATH:	/home/nfs
WEB_IP:	192.168.0.24
WEB_PORT:	8000
WEB_VIDEO_STAT_ENPOINT:	http://${WEB_IP}:${WEB_PORT}/api/contest/videos/status/
/usr/local/lib/python3.6/site-packages/celery/platforms.py:796: RuntimeWarning: You're running the worker with superuser privileges: this is
absolutely not recommended!

Please specify a different user using the --uid option.

User information: uid=0 euid=0 gid=0 egid=0

  uid=uid, euid=euid, gid=gid, egid=egid,
[2018-10-14 23:17:21,585: INFO/MainProcess] Connected to amqp://aucar:**@172.17.0.2:5672/aucar
[2018-10-14 23:17:21,600: INFO/MainProcess] mingle: searching for neighbors
[2018-10-14 23:17:22,755: INFO/MainProcess] mingle: all alone
[2018-10-14 23:17:22,783: INFO/MainProcess] celery@aaa352c418bb ready.
[2018-10-14 23:17:26,427: INFO/MainProcess] Events of group {task} enabled by remote.
[2018-10-14 23:18:06,944: INFO/MainProcess] Received task: tasks.process_video[30d93d5e-2e77-4999-b2b1-5c4b9f21858e]  
/usr/local/lib/python3.6/site-packages/celery/platforms.py:796: RuntimeWarning: You're running the worker with superuser privileges: this is
absolutely not recommended!

Please specify a different user using the --uid option.

User information: uid=0 euid=0 gid=0 egid=0

  uid=uid, euid=euid, gid=gid, egid=egid,
[2018-10-14 23:18:06,947: INFO/ForkPoolWorker-1] Start processing /home/nfs/media/contests/videos/worker1_6ChlH94.webm to /home/nfs/media/contests/videos/worker1_6ChlH94._Converted.mp4
[2018-10-14 23:18:07,474: ERROR/ForkPoolWorker-1]  ffmpeg version 3.2.12-1~deb9u1 Copyright (c) 2000-2018 the FFmpeg developers
  built with gcc 6.3.0 (Debian 6.3.0-18+deb9u1) 20170516
  configuration: --prefix=/usr --extra-version='1~deb9u1' --toolchain=hardened --libdir=/usr/lib/x86_64-linux-gnu --incdir=/usr/include/x86_64-linux-gnu --enable-gpl --disable-stripping --enable-avresample --enable-avisynth --enable-gnutls --enable-ladspa --enable-libass --enable-libbluray --enable-libbs2b --enable-libcaca --enable-libcdio --enable-libebur128 --enable-libflite --enable-libfontconfig --enable-libfreetype --enable-libfribidi --enable-libgme --enable-libgsm --enable-libmp3lame --enable-libopenjpeg --enable-libopenmpt --enable-libopus --enable-libpulse --enable-librubberband --enable-libshine --enable-libsnappy --enable-libsoxr --enable-libspeex --enable-libssh --enable-libtheora --enable-libtwolame --enable-libvorbis --enable-libvpx --enable-libwavpack --enable-libwebp --enable-libx265 --enable-libxvid --enable-libzmq --enable-libzvbi --enable-omx --enable-openal --enable-opengl --enable-sdl2 --enable-libdc1394 --enable-libiec61883 --enable-chromaprint --enable-frei0r --enable-libopencv --enable-libx264 --enable-shared
  libavutil      55. 34.101 / 55. 34.101
  libavcodec     57. 64.101 / 57. 64.101
  libavformat    57. 56.101 / 57. 56.101
  libavdevice    57.  1.100 / 57.  1.100
  libavfilter     6. 65.100 /  6. 65.100
  libavresample   3.  1.  0 /  3.  1.  0
  libswscale      4.  2.100 /  4.  2.100
  libswresample   2.  3.100 /  2.  3.100
  libpostproc    54.  1.100 / 54.  1.100
/home/nfs/media/contests/videos/worker1_6ChlH94.webm: No such file or directory
 /home/nfs/media/contests/videos/worker1_6ChlH94.webm
[2018-10-14 23:18:07,474: ERROR/ForkPoolWorker-1]  ffmpeg version 3.2.12-1~deb9u1 Copyright (c) 2000-2018 the FFmpeg developers
  built with gcc 6.3.0 (Debian 6.3.0-18+deb9u1) 20170516
  configuration: --prefix=/usr --extra-version='1~deb9u1' --toolchain=hardened --libdir=/usr/lib/x86_64-linux-gnu --incdir=/usr/include/x86_64-linux-gnu --enable-gpl --disable-stripping --enable-avresample --enable-avisynth --enable-gnutls --enable-ladspa --enable-libass --enable-libbluray --enable-libbs2b --enable-libcaca --enable-libcdio --enable-libebur128 --enable-libflite --enable-libfontconfig --enable-libfreetype --enable-libfribidi --enable-libgme --enable-libgsm --enable-libmp3lame --enable-libopenjpeg --enable-libopenmpt --enable-libopus --enable-libpulse --enable-librubberband --enable-libshine --enable-libsnappy --enable-libsoxr --enable-libspeex --enable-libssh --enable-libtheora --enable-libtwolame --enable-libvorbis --enable-libvpx --enable-libwavpack --enable-libwebp --enable-libx265 --enable-libxvid --enable-libzmq --enable-libzvbi --enable-omx --enable-openal --enable-opengl --enable-sdl2 --enable-libdc1394 --enable-libiec61883 --enable-chromaprint --enable-frei0r --enable-libopencv --enable-libx264 --enable-shared
  libavutil      55. 34.101 / 55. 34.101
  libavcodec     57. 64.101 / 57. 64.101
  libavformat    57. 56.101 / 57. 56.101
  libavdevice    57.  1.100 / 57.  1.100
  libavfilter     6. 65.100 /  6. 65.100
  libavresample   3.  1.  0 /  3.  1.  0
  libswscale      4.  2.100 /  4.  2.100
  libswresample   2.  3.100 /  2.  3.100
  libpostproc    54.  1.100 / 54.  1.100
/home/nfs/media/contests/videos/worker1_6ChlH94.webm: No such file or directory
 /media/contests/videos/worker1_6ChlH94.webm
[2018-10-14 23:18:07,492: INFO/ForkPoolWorker-1] Task tasks.process_video[30d93d5e-2e77-4999-b2b1-5c4b9f21858e] succeeded in 0.545472460999008s: 1
INFO : 2018-10-14 23:30:20,201 : Running with settings
NFS_PATH:	/home/app/nfs
WEB_IP:	192.168.0.24
WEB_PORT:	8000
WEB_VIDEO_STAT_ENPOINT:	http://${WEB_IP}:${WEB_PORT}/api/contest/videos/status/
Running with settings
NFS_PATH:	/home/app/nfs
WEB_IP:	192.168.0.24
WEB_PORT:	8000
WEB_VIDEO_STAT_ENPOINT:	http://${WEB_IP}:${WEB_PORT}/api/contest/videos/status/
/usr/local/lib/python3.6/site-packages/celery/platforms.py:796: RuntimeWarning: You're running the worker with superuser privileges: this is
absolutely not recommended!

Please specify a different user using the --uid option.

User information: uid=0 euid=0 gid=0 egid=0

  uid=uid, euid=euid, gid=gid, egid=egid,
[2018-10-14 23:30:20,344: INFO/MainProcess] Connected to amqp://aucar:**@172.17.0.2:5672/aucar
[2018-10-14 23:30:20,361: INFO/MainProcess] mingle: searching for neighbors
[2018-10-14 23:30:21,612: INFO/MainProcess] mingle: all alone
[2018-10-14 23:30:21,637: INFO/MainProcess] celery@f0343813f5c7 ready.
[2018-10-14 23:30:25,240: INFO/MainProcess] Events of group {task} enabled by remote.
[2018-10-14 23:31:05,735: INFO/MainProcess] Received task: tasks.process_video[affcee08-7753-4b76-a99d-07c2bb8cc27b]  
/usr/local/lib/python3.6/site-packages/celery/platforms.py:796: RuntimeWarning: You're running the worker with superuser privileges: this is
absolutely not recommended!

Please specify a different user using the --uid option.

User information: uid=0 euid=0 gid=0 egid=0

  uid=uid, euid=euid, gid=gid, egid=egid,
[2018-10-14 23:31:05,738: INFO/ForkPoolWorker-1] Start processing /home/app/nfs/media/contests/videos/worker1_MYO13jh.webm to /home/app/nfs/media/contests/videos/worker1_MYO13jh._Converted.mp4
[2018-10-14 23:31:21,869: INFO/ForkPoolWorker-1] End processing file /home/app/nfs/media/contests/videos/worker1_MYO13jh.webm
[2018-10-14 23:31:21,869: INFO/ForkPoolWorker-1] Process success /media/contests/videos/worker1_MYO13jh.webm
[2018-10-14 23:31:21,899: ERROR/ForkPoolWorker-1] Task tasks.process_video[affcee08-7753-4b76-a99d-07c2bb8cc27b] raised unexpected: InvalidURL('Failed to parse: ${WEB_IP}:${WEB_PORT}',)
Traceback (most recent call last):
  File "/usr/local/lib/python3.6/site-packages/requests/models.py", line 375, in prepare_url
    scheme, auth, host, port, path, query, fragment = parse_url(url)
  File "/usr/local/lib/python3.6/site-packages/urllib3/util/url.py", line 199, in parse_url
    raise LocationParseError(url)
urllib3.exceptions.LocationParseError: Failed to parse: ${WEB_IP}:${WEB_PORT}

During handling of the above exception, another exception occurred:

Traceback (most recent call last):
  File "/usr/local/lib/python3.6/site-packages/celery/app/trace.py", line 382, in trace_task
    R = retval = fun(*args, **kwargs)
  File "/usr/local/lib/python3.6/site-packages/celery/app/trace.py", line 641, in __protected_call__
    return self.run(*args, **kwargs)
  File "/home/app/celery/tasks.py", line 21, in process_video
    return process_client_video(domain_url, video_id, input_file, output_file)
  File "/home/app/celery/processing.py", line 125, in process_client_video
    notify_client(domain_url,video_id)
  File "/home/app/celery/processing.py", line 146, in notify_client
    data= {'video_id':video_id}
  File "/usr/local/lib/python3.6/site-packages/requests/api.py", line 112, in post
    return request('post', url, data=data, json=json, **kwargs)
  File "/usr/local/lib/python3.6/site-packages/requests/api.py", line 58, in request
    return session.request(method=method, url=url, **kwargs)
  File "/usr/local/lib/python3.6/site-packages/requests/sessions.py", line 498, in request
    prep = self.prepare_request(req)
  File "/usr/local/lib/python3.6/site-packages/requests/sessions.py", line 441, in prepare_request
    hooks=merge_hooks(request.hooks, self.hooks),
  File "/usr/local/lib/python3.6/site-packages/requests/models.py", line 309, in prepare
    self.prepare_url(url, params)
  File "/usr/local/lib/python3.6/site-packages/requests/models.py", line 377, in prepare_url
    raise InvalidURL(*e.args)
requests.exceptions.InvalidURL: Failed to parse: ${WEB_IP}:${WEB_PORT}
INFO : 2018-10-14 23:38:09,891 : Running with settings
NFS_PATH:	/home/app/nfs
WEB_IP:	192.168.0.24
WEB_PORT:	8000
WEB_VIDEO_STAT_ENPOINT:	http://192.168.0.24:8000/api/contest/videos/status/
Running with settings
NFS_PATH:	/home/app/nfs
WEB_IP:	192.168.0.24
WEB_PORT:	8000
WEB_VIDEO_STAT_ENPOINT:	http://192.168.0.24:8000/api/contest/videos/status/
/usr/local/lib/python3.6/site-packages/celery/platforms.py:796: RuntimeWarning: You're running the worker with superuser privileges: this is
absolutely not recommended!

Please specify a different user using the --uid option.

User information: uid=0 euid=0 gid=0 egid=0

  uid=uid, euid=euid, gid=gid, egid=egid,
[2018-10-14 23:38:10,041: INFO/MainProcess] Connected to amqp://aucar:**@172.17.0.2:5672/aucar
[2018-10-14 23:38:10,057: INFO/MainProcess] mingle: searching for neighbors
[2018-10-14 23:38:11,176: INFO/MainProcess] mingle: all alone
[2018-10-14 23:38:11,282: INFO/MainProcess] celery@e1bbe036c233 ready.
[2018-10-14 23:38:14,939: INFO/MainProcess] Events of group {task} enabled by remote.
[2018-10-14 23:40:03,526: INFO/MainProcess] Received task: tasks.process_video[beb0e150-eecf-4add-8cc0-72087f6190f3]  
/usr/local/lib/python3.6/site-packages/celery/platforms.py:796: RuntimeWarning: You're running the worker with superuser privileges: this is
absolutely not recommended!

Please specify a different user using the --uid option.

User information: uid=0 euid=0 gid=0 egid=0

  uid=uid, euid=euid, gid=gid, egid=egid,
[2018-10-14 23:40:03,529: INFO/ForkPoolWorker-1] Start processing /home/app/nfs/media/contests/videos/worker1_nlmOuMn.webm to /home/app/nfs/media/contests/videos/worker1_nlmOuMn._Converted.mp4
[2018-10-14 23:40:18,264: INFO/ForkPoolWorker-1] End processing file /home/app/nfs/media/contests/videos/worker1_nlmOuMn.webm
[2018-10-14 23:40:18,264: INFO/ForkPoolWorker-1] Process success /media/contests/videos/worker1_nlmOuMn.webm
[2018-10-14 23:40:18,302: ERROR/ForkPoolWorker-1] Task tasks.process_video[beb0e150-eecf-4add-8cc0-72087f6190f3] raised unexpected: ConnectionError(MaxRetryError("HTTPConnectionPool(host='192.168.0.24', port=8000): Max retries exceeded with url: /api/contest/videos/status/ (Caused by NewConnectionError('<urllib3.connection.HTTPConnection object at 0x7f035c80aac8>: Failed to establish a new connection: [Errno 111] Connection refused',))",),)
Traceback (most recent call last):
  File "/usr/local/lib/python3.6/site-packages/urllib3/connection.py", line 171, in _new_conn
    (self._dns_host, self.port), self.timeout, **extra_kw)
  File "/usr/local/lib/python3.6/site-packages/urllib3/util/connection.py", line 79, in create_connection
    raise err
  File "/usr/local/lib/python3.6/site-packages/urllib3/util/connection.py", line 69, in create_connection
    sock.connect(sa)
ConnectionRefusedError: [Errno 111] Connection refused

During handling of the above exception, another exception occurred:

Traceback (most recent call last):
  File "/usr/local/lib/python3.6/site-packages/urllib3/connectionpool.py", line 600, in urlopen
    chunked=chunked)
  File "/usr/local/lib/python3.6/site-packages/urllib3/connectionpool.py", line 354, in _make_request
    conn.request(method, url, **httplib_request_kw)
  File "/usr/local/lib/python3.6/http/client.py", line 1239, in request
    self._send_request(method, url, body, headers, encode_chunked)
  File "/usr/local/lib/python3.6/http/client.py", line 1285, in _send_request
    self.endheaders(body, encode_chunked=encode_chunked)
  File "/usr/local/lib/python3.6/http/client.py", line 1234, in endheaders
    self._send_output(message_body, encode_chunked=encode_chunked)
  File "/usr/local/lib/python3.6/http/client.py", line 1026, in _send_output
    self.send(msg)
  File "/usr/local/lib/python3.6/http/client.py", line 964, in send
    self.connect()
  File "/usr/local/lib/python3.6/site-packages/urllib3/connection.py", line 196, in connect
    conn = self._new_conn()
  File "/usr/local/lib/python3.6/site-packages/urllib3/connection.py", line 180, in _new_conn
    self, "Failed to establish a new connection: %s" % e)
urllib3.exceptions.NewConnectionError: <urllib3.connection.HTTPConnection object at 0x7f035c80aac8>: Failed to establish a new connection: [Errno 111] Connection refused

During handling of the above exception, another exception occurred:

Traceback (most recent call last):
  File "/usr/local/lib/python3.6/site-packages/requests/adapters.py", line 445, in send
    timeout=timeout
  File "/usr/local/lib/python3.6/site-packages/urllib3/connectionpool.py", line 638, in urlopen
    _stacktrace=sys.exc_info()[2])
  File "/usr/local/lib/python3.6/site-packages/urllib3/util/retry.py", line 398, in increment
    raise MaxRetryError(_pool, url, error or ResponseError(cause))
urllib3.exceptions.MaxRetryError: HTTPConnectionPool(host='192.168.0.24', port=8000): Max retries exceeded with url: /api/contest/videos/status/ (Caused by NewConnectionError('<urllib3.connection.HTTPConnection object at 0x7f035c80aac8>: Failed to establish a new connection: [Errno 111] Connection refused',))

During handling of the above exception, another exception occurred:

Traceback (most recent call last):
  File "/usr/local/lib/python3.6/site-packages/celery/app/trace.py", line 382, in trace_task
    R = retval = fun(*args, **kwargs)
  File "/usr/local/lib/python3.6/site-packages/celery/app/trace.py", line 641, in __protected_call__
    return self.run(*args, **kwargs)
  File "/home/app/celery/tasks.py", line 21, in process_video
    return process_client_video(domain_url, video_id, input_file, output_file)
  File "/home/app/celery/processing.py", line 125, in process_client_video
    notify_client(domain_url,video_id)
  File "/home/app/celery/processing.py", line 146, in notify_client
    data= {'video_id':video_id}
  File "/usr/local/lib/python3.6/site-packages/requests/api.py", line 112, in post
    return request('post', url, data=data, json=json, **kwargs)
  File "/usr/local/lib/python3.6/site-packages/requests/api.py", line 58, in request
    return session.request(method=method, url=url, **kwargs)
  File "/usr/local/lib/python3.6/site-packages/requests/sessions.py", line 512, in request
    resp = self.send(prep, **send_kwargs)
  File "/usr/local/lib/python3.6/site-packages/requests/sessions.py", line 622, in send
    r = adapter.send(request, **kwargs)
  File "/usr/local/lib/python3.6/site-packages/requests/adapters.py", line 513, in send
    raise ConnectionError(e, request=request)
requests.exceptions.ConnectionError: HTTPConnectionPool(host='192.168.0.24', port=8000): Max retries exceeded with url: /api/contest/videos/status/ (Caused by NewConnectionError('<urllib3.connection.HTTPConnection object at 0x7f035c80aac8>: Failed to establish a new connection: [Errno 111] Connection refused',))
[2018-10-14 23:44:06,693: INFO/MainProcess] Received task: tasks.process_video[0c955520-e555-4f10-a66d-e339a95a74b2]  
[2018-10-14 23:44:06,694: INFO/ForkPoolWorker-1] Start processing /home/app/nfs/media/contests/videos/Invencible_UISNtJO.avi to /home/app/nfs/media/contests/videos/Invencible_UISNtJO_Converted.mp4
[2018-10-14 23:48:04,029: INFO/ForkPoolWorker-1] End processing file /home/app/nfs/media/contests/videos/Invencible_UISNtJO.avi
[2018-10-14 23:48:04,029: INFO/ForkPoolWorker-1] Process success /media/contests/videos/Invencible_UISNtJO.avi
[2018-10-14 23:48:07,210: INFO/ForkPoolWorker-1] Notification sended to facebook.aucarvideo.com about video 36
[2018-10-14 23:48:07,228: INFO/ForkPoolWorker-1] Task tasks.process_video[0c955520-e555-4f10-a66d-e339a95a74b2] succeeded in 240.5339988779997s: 0
